Workbook

Sheet Orders
A1: TeensyMaestro Board Set Orders | E1: Contacted | F1: Invoiced | G1: Paid | H1: Shipped
A4: Name | B4: Call | C4: Board sets | D4: Kits | E4: Email | F4: Address | G4: PCB Set Cost | H4: Envelope Cost | I4: Ship cost@ 6 oz | J4: SUBtotal | K4: Tax | L4: Paypal Fee | M4: Total
A5: Kasey Efaw | B5: KD2YMM | C5: 2 | E5: kd2ymm@gmail.com | F5: 14 Highland Road, Amsterdam, NY 12010 | G5: =C5*5 -> 10 | H5: 0.5 | I5: 5.83 | J5: =G5+H5+I5 -> 16.33 | K5: =J5*0.0825 -> 1.347225 | L5: =(J5+K5)*0.05 -> 0.88386125 | M5: =J5+K5+L5 -> 18.561086
A6: Joe Camilli | B6: N7QPP | C6: 1 | D6: 1 | E6: jjcamilli@hotmail.com | F6: 3660 Preakness ln, Suwannee, GA 30024 | G6: =C6*5 -> 5 | H6: 0.5 | I6: 4.74 | J6: =G6+H6+I6 -> 10.24 | K6: =J6*0.0825 -> 0.8448 | L6: =(J6+K6)*0.05 -> 0.55424 | M6: =J6+K6+L6 -> 11.63904
A7: Michael Morgan | B7: AA5SH | C7: 2 | D7: 1 | E7: cmorgan13@gmail.com | F7: 30994 La Highway 16, Denham Springs, LA 70726 | G7: =5.8*Orders!C7 -> 11.6 | H7: 0.5 | I7: 5.34 | J7: =G7+H7+I7 -> 17.44 | K7: =J7*0.0825 -> 1.4388 | L7: =(J7+K7)*0.05 -> 0.94394 | M7: =J7+K7+L7 -> 19.82274
A8: Kirk Harding | B8: K6KAR | C8: 0 | D8: 1 | E8: kirk.harding@k6kar.com | F8: 835 Golden Pond Court, Osprey, FL 34229 | G8: =5.8*Orders!C8 -> 0 | H8: 0.5 | J8: =G8+H8+I8 -> 0.5 | K8: =J8*0.0825 -> 0.04125 | L8: =(J8+K8)*0.05 -> 0.0270625 | M8: =J8+K8+L8 -> 0.5683125 | N8: Suite AU49424, 4283 Express Lane, Sarasota FL 34249
A9: Brett Mills | B9: WX7Y | C9: 5 | D9: 0 | E9: bret.wx7y@wx7y.net | F9: P.O. Box 1161, Castle Dale, Utah 84513 | G9: =5.8*Orders!C9 -> 29 | H9: 1.5 | I9: 8.46 | J9: =G9+H9+I9 -> 38.96 | K9: =J9*0.0825 -> 3.2142 | L9: =(J9+K9)*0.05 -> 2.10871 | M9: =J9+K9+L9 -> 44.28291
A10: Clifford Miller | B10: W4CMM | C10: 1 | D10: 1 | E10: clifford@millerlawoffices.us | F10: 916 47th Ave, Vero Beach FL 32966 | G10: =5.8*Orders!C10 -> 5.8 | H10: 0.5 | I10: 4.41 | J10: =G10+H10+I10 -> 10.71 | K10: =J10*0.0825 -> 0.883575 | L10: =(J10+K10)*0.05 -> 0.57967875 | M10: =J10+K10+L10 -> 12.173254
A11: Warren Volz | B11: KD5YPH | C11: 1 | D11: 0 | E11: warren@warrenvolz.com | F11: 3040 Albion St, Denver, CO 80207 | G11: =5.8*Orders!C11 -> 5.8 | H11: 0.5 | I11: 4.74 | J11: =G11+H11+I11 -> 11.04 | K11: =J11*0.0825 -> 0.9108 | L11: =(J11+K11)*0.05 -> 0.59754 | M11: =J11+K11+L11 -> 12.54834
A12: Sam R Burnes | B12: WY8V | C12: 1 | D12: 1 | E12: sburnes@icloud.com | F12: 3075 Boys Ranch Road, Kempner, Texas 76539 | G12: =5.8*Orders!C12 -> 5.8 | H12: 0.5 | I12: 4.74 | J12: =G12+H12+I12 -> 11.04 | K12: =J12*0.0825 -> 0.9108 | L12: =(J12+K12)*0.05 -> 0.59754 | M12: =J12+K12+L12 -> 12.54834
A13: Ray Spargo | B13: VK5RR | C13: 0 | D13: 2 | E13: vk5rr@vk5rr.com | F13: 28 Pearson St, Parafield Gardens South Australia 5107, Australia | G13: =5.8*Orders!C13 -> 0 | H13: 0.5 | J13: =G13+H13+I13 -> 0.5 | K13: =J13*0.0825 -> 0.04125 | L13: =(J13+K13)*0.05 -> 0.0270625 | M13: =J13+K13+L13 -> 0.5683125 | N13: PO Box 2900, Adelaide South, Australia 5107
A14: Greg Fischer | B14: AB7R | C14: 2 | D14: 0 | E14: jitters61@pm.me | F14: 19127 Kenney Way, Caldwell, Idaho. 83605 | G14: =5.8*Orders!C14 -> 11.6 | H14: 0.5 | I14: 4.89 | J14: =G14+H14+I14 -> 16.99 | K14: =J14*0.0825 -> 1.401675 | L14: =(J14+K14)*0.05 -> 0.91958375 | M14: =J14+K14+L14 -> 19.311259
A15: Watts Hill | B15: K4QJZ | C15: 1 | D15: 1 | E15: watts.hill@gmail.com | F15: 208 Mountain Top Road, Front Royal, VA 22630 | G15: =5.8*Orders!C15 -> 5.8 | H15: 0.5 | I15: 4.8 | J15: =G15+H15+I15 -> 11.1 | K15: =J15*0.0825 -> 0.91575 | L15: =(J15+K15)*0.05 -> 0.6007875 | M15: =J15+K15+L15 -> 12.616537
A16: Ron Panetta | B16: WB2WGH | C16: 5 | D16: 0 | E16: ron@panman.us | F16: 7913 Walking Stick Way, Liverpool, NY 13090 | G16: =5.8*Orders!C16 -> 29 | H16: 1.5 | I16: 8.63 | J16: =G16+H16+I16 -> 39.13 | K16: =J16*0.0825 -> 3.228225 | L16: =(J16+K16)*0.05 -> 2.1179113 | M16: =J16+K16+L16 -> 44.476136
A17: Steve Boston | B17: K2SAB | C17: 0 | D17: 1 | E17: stevenk2sab@gmail.com | F17: ? | G17: =5.8*Orders!C17 -> 0 | H17: 0.5 | J17: =G17+H17+I17 -> 0.5 | K17: =J17*0.0825 -> 0.04125 | L17: =(J17+K17)*0.05 -> 0.0270625 | M17: =J17+K17+L17 -> 0.5683125
A18: Jim Kauten | B18: W4TE | C18: 0 | D18: 1 | E18: kautenmd@gmail.com | F18: 558 Arden Oak Ct , Atlanta, GA 30305 | G18: =5.8*Orders!C18 -> 0 | H18: 0.5 | J18: =G18+H18+I18 -> 0.5 | K18: =J18*0.0825 -> 0.04125 | L18: =(J18+K18)*0.05 -> 0.0270625 | M18: =J18+K18+L18 -> 0.5683125
A19: Martin Koechel | B19: KW1M | C19: 0 | D19: 1 | E19: kw1m@outlook.com | F19: 876 Plausawa Hill Road , Pembroke, NH 03275 | G19: =5.8*Orders!C19 -> 0 | H19: 0.5 | J19: =G19+H19+I19 -> 0.5 | K19: =J19*0.0825 -> 0.04125 | L19: =(J19+K19)*0.05 -> 0.0270625 | M19: =J19+K19+L19 -> 0.5683125
A20: Walter Holmes | B20: K5WH | C20: 0 | D20: 3 | E20: walterh@k5wh.net | F20: 10726 Crestfield Ct., Houston, Tx. 77070 | G20: =5.8*Orders!C20 -> 0 | H20: 0.5 | J20: =G20+H20+I20 -> 0.5 | K20: =J20*0.0825 -> 0.04125 | L20: =(J20+K20)*0.05 -> 0.0270625 | M20: =J20+K20+L20 -> 0.5683125
A21: Danny Pease | B21: W9DP | C21: 1 | D21: 0 | E21: w9dp@w9dp.us | F21: 306 S. Illinois , Camp Point, IL 62320 | G21: =5.8*Orders!C21 -> 5.8 | H21: 0.5 | I21: 4.91 | J21: =G21+H21+I21 -> 11.21 | K21: =J21*0.0825 -> 0.924825 | L21: =(J21+K21)*0.05 -> 0.60674125 | M21: =J21+K21+L21 -> 12.741566
A22: Steve Sterling | B22: WA7DUH | C22: 2 | D22: 2 | E22: wa7duh@sgsterling.com | F22: 26711 Dallas RD, Richland, WA 99352 | G22: =5.8*Orders!C22 -> 11.6 | H22: 0.5 | I22: 5.83 | J22: =G22+H22+I22 -> 17.93 | K22: =J22*0.0825 -> 1.479225 | L22: =(J22+K22)*0.05 -> 0.97046125 | M22: =J22+K22+L22 -> 20.379686
A23: Steve Zumbrun | B23: W0SZ | C23: 0 | D23: 2 | E23: w0sz@comcast.net | F23: 2655 65th Ave, Greeley CO 80634-8904 | G23: =5.8*Orders!C23 -> 0 | H23: 0.5 | J23: =G23+H23+I23 -> 0.5 | K23: =J23*0.0825 -> 0.04125 | L23: =(J23+K23)*0.05 -> 0.0270625 | M23: =J23+K23+L23 -> 0.5683125
A24: James Boehner | B24: N2ZZ | C24: 0 | D24: 0 | E24: jboehner01@yahoo.com | F24: ? | G24: =5.8*Orders!C24 -> 0 | H24: 0.5 | J24: =G24+H24+I24 -> 0.5 | K24: =J24*0.0825 -> 0.04125 | L24: =(J24+K24)*0.05 -> 0.0270625 | M24: =J24+K24+L24 -> 0.5683125
A25: Jerry Stern | B25: NY2KW | C25: 2 | D25: 1 | E25: jsternmd@gmail.com | F25: 58 Orchard Hill Rd, Katonah, NY, 10536 | G25: =5.8*Orders!C25 -> 11.6 | H25: 0.5 | I25: 5.83 | J25: =G25+H25+I25 -> 17.93 | K25: =J25*0.0825 -> 1.479225 | L25: =(J25+K25)*0.05 -> 0.97046125 | M25: =J25+K25+L25 -> 20.379686
A26: Don Pezet | B26: K4PEZ | C26: 0 | D26: 1 | E26: don@thepezets.com | F26: ? | G26: =5.8*Orders!C26 -> 0 | H26: 0.5 | J26: =G26+H26+I26 -> 0.5 | K26: =J26*0.0825 -> 0.04125 | L26: =(J26+K26)*0.05 -> 0.0270625 | M26: =J26+K26+L26 -> 0.5683125
A27: Robin Alexander | B27: W7YED | C27: 2 | D27: 0 | E27: robin@tartanlatte.com | F27: 16619 NE 160th St,, Woodinville, WA 98072 | G27: =5.8*Orders!C27 -> 11.6 | H27: 0.5 | I27: 6.02 | J27: =G27+H27+I27 -> 18.12 | K27: =J27*0.0825 -> 1.4949 | L27: =(J27+K27)*0.05 -> 0.980745 | M27: =J27+K27+L27 -> 20.595645
A28: Tom Williams | B28: WA1MBA | C28: 0 | D28: 1 | E28: Tomw3141@gmail.com | F28: ? | G28: =5.8*Orders!C28 -> 0 | H28: 0.5 | J28: =G28+H28+I28 -> 0.5 | K28: =J28*0.0825 -> 0.04125 | L28: =(J28+K28)*0.05 -> 0.0270625 | M28: =J28+K28+L28 -> 0.5683125
A29: John Simmons | B29: NI0K | C29: 1 | D29: 0 | E29: jasimmons@pinewooddata.com | F29: 26189 President DR NW, Shevlin MN 56676 | G29: =5.8*Orders!C29 -> 5.8 | H29: 0.5 | I29: 4.97 | J29: =G29+H29+I29 -> 11.27 | K29: =J29*0.0825 -> 0.929775 | L29: =(J29+K29)*0.05 -> 0.60998875 | M29: =J29+K29+L29 -> 12.809764 | N29: FPs only
A30: Don Rand | B30: WV5Q | C30: 0 | D30: 0 | E30: don.rand@gmail.com | F30: 9205 Ashburn Rd, Vancleave, MS 39565 | G30: =5.8*Orders!C30 -> 0 | H30: 0.5 | J30: =G30+H30+I30 -> 0.5 | K30: =J30*0.0825 -> 0.04125 | L30: =(J30+K30)*0.05 -> 0.0270625 | M30: =J30+K30+L30 -> 0.5683125
A31: James Hurry | B31: WA5QPZ | C31: 0 | D31: 2 | E31: wa5qpz@gmail.com | F31: 201 Mesa Verde Dr., Cedar Creek, Texas. 78612 | G31: =5.8*Orders!C31 -> 0 | H31: 0.5 | J31: =G31+H31+I31 -> 0.5 | K31: =J31*0.0825 -> 0.04125 | L31: =(J31+K31)*0.05 -> 0.0270625 | M31: =J31+K31+L31 -> 0.5683125
A32: Saad Mahaini | B32: N5FF | C32: 2 | D32: 0 | E32: n5ff@yahoo.com | F32: 20 Edgefield Ln, Lucas, TX 75002 | G32: =5.8*Orders!C32 -> 11.6 | H32: 0.5 | I32: 5.34 | J32: =G32+H32+I32 -> 17.44 | K32: =J32*0.0825 -> 1.4388 | L32: =(J32+K32)*0.05 -> 0.94394 | M32: =J32+K32+L32 -> 19.82274
A33: Ed Ireland | B33: K5YZW | C33: 0 | D33: 1 | E33: ed@edireland.com | F33: 8625 Davis Blvd, Apt 2201, North Richland Hills, TX 76182 | G33: =5.8*Orders!C33 -> 0 | H33: 0.5 | J33: =G33+H33+I33 -> 0.5 | K33: =J33*0.0825 -> 0.04125 | L33: =(J33+K33)*0.05 -> 0.0270625 | M33: =J33+K33+L33 -> 0.5683125
A34: Ken Kayser | B34: K2KXK | C34: 1 | D34: 0 | E34: kxkayser@gmail.com | F34: 1101 Nauvoo Ridge Dr., Tobaccoville, NC 27050 | G34: =5.8*Orders!C34 -> 5.8 | H34: 0.5 | I34: 4.8 | J34: =G34+H34+I34 -> 11.1 | K34: =J34*0.0825 -> 0.91575 | L34: =(J34+K34)*0.05 -> 0.6007875 | M34: =J34+K34+L34 -> 12.616537
A35: Marty Purselly | B35: AA5UN | C35: 0 | D35: 1 | E35: aa5un2020@gmail.com | F35: Granbury, Texas | G35: =5.8*Orders!C35 -> 0 | H35: 0.5 | J35: =G35+H35+I35 -> 0.5 | K35: =J35*0.0825 -> 0.04125 | L35: =(J35+K35)*0.05 -> 0.0270625 | M35: =J35+K35+L35 -> 0.5683125 | N35: purselley@gmail.com for paypal
A36: Richard Pestinger | B36: KC8RP | C36: 1 | D36: 0 | E36: rpestinger@gmail.com | F36: 9195 Georgetown Cir, Loveland, OH 45140 | G36: =5.8*Orders!C36 -> 5.8 | H36: 0.5 | I36: 4.74 | J36: =G36+H36+I36 -> 11.04 | K36: =J36*0.0825 -> 0.9108 | L36: =(J36+K36)*0.05 -> 0.59754 | M36: =J36+K36+L36 -> 12.54834
A37: George Levar | B37: NQ9N | C37: 0 | D37: 2 | E37: george@NQ9N.com | F37: ? | G37: =5.8*Orders!C37 -> 0 | H37: 0.5 | J37: =G37+H37+I37 -> 0.5 | K37: =J37*0.0825 -> 0.04125 | L37: =(J37+K37)*0.05 -> 0.0270625 | M37: =J37+K37+L37 -> 0.5683125
A38: David Parker | B38: N4ASA | C38: 2 | D38: 0 | E38: n4asa@yahoo.com | F38: 924 Pool Street, Biddeford, ME 04005 | G38: =5.8*Orders!C38 -> 11.6 | H38: 0.5 | I38: 5.83 | J38: =G38+H38+I38 -> 17.93 | K38: =J38*0.0825 -> 1.479225 | L38: =(J38+K38)*0.05 -> 0.97046125 | M38: =J38+K38+L38 -> 20.379686
A39: Michael LaFleur | B39: K8QKJ | C39: 2 | D39: 1 | E39: mplafleur@gmail.com | F39: 27670 California Dr SE, Lathrup Village, MI 48076 | G39: =5.8*Orders!C39 -> 11.6 | H39: 0.5 | I39: 5.7 | J39: =G39+H39+I39 -> 17.8 | K39: =J39*0.0825 -> 1.4685 | L39: =(J39+K39)*0.05 -> 0.963425 | M39: =J39+K39+L39 -> 20.231925
A40: Gordon Howell | B40: WA4RTS | C40: 0 | D40: 1 | E40: gphowell@icloud.com | F40: 201 Irvington Street, Lynchburg, VA. 24503 | G40: =5.8*Orders!C40 -> 0 | H40: 0.5 | J40: =G40+H40+I40 -> 0.5 | K40: =J40*0.0825 -> 0.04125 | L40: =(J40+K40)*0.05 -> 0.0270625 | M40: =J40+K40+L40 -> 0.5683125
A41: Norman Heyen | B41: KC9NVN | C41: 0 | D41: 1 | E41: norman.heyen@gmail.com | F41: 1032 Burke Drive , Freeport, IL 61032 | G41: =5.8*Orders!C41 -> 0 | H41: 0.5 | J41: =G41+H41+I41 -> 0.5 | K41: =J41*0.0825 -> 0.04125 | L41: =(J41+K41)*0.05 -> 0.0270625 | M41: =J41+K41+L41 -> 0.5683125
A42: Shanon Herron | B42: KA8SPW | C42: 2 | D42: 2 | E42: ka8spw@gmail.com | F42: 1679 Topinabee Mail Route Rd., Cheboygan, Michigan 49721 | G42: =5.8*Orders!C42 -> 11.6 | H42: 0.5 | I42: 5.9 | J42: =G42+H42+I42 -> 18 | K42: =J42*0.0825 -> 1.485 | L42: =(J42+K42)*0.05 -> 0.97425 | M42: =J42+K42+L42 -> 20.45925
...

Sheet Materials
E1: Shipping | F1: Tax | G1: Tariff | H1: PP Fee | J1: Cost per | M1: PCB | N1: FP | O1: PCB+FP
E2: 169.04 | F2: 27.11 | G2: 144.05 | H2: 2.87 | L2: Materials | M2: =C3/A3 -> 1.202 | N2: =C4/A4 -> 1.309 | O2: =M2+N2 -> 2.511
A3: 100 | B3: TM PCB | C3: 120.2 | D3: =C3/C6 -> 0.4589538 | E3: =E2*$D3 -> 77.58155 | F3: =F2*$D3 -> 12.442237 | G3: =G2*$D3 -> 66.112295 | H3: =H2*$D3 -> 1.3171974 | J3: =(C3+E3+F3+G3+H3)/A3 -> 2.7765328 | L3: Shipping | M3: =E3/A3 -> 0.7758155 | N3: =E4/A4 -> 0.84487728 | O3: =M3+N3 -> 1.6206928
A4: 100 | B4: TM FP | C4: 130.9 | D4: =C4/C6 -> 0.49980909 | E4: =E2*$D4 -> 84.487728 | F4: =F2*$D4 -> 13.549824 | G4: =G2*$D4 -> 71.997499 | H4: =H2*$D4 -> 1.4344521 | J4: =(C4+E4+F4+G4+H4)/A4 -> 3.023695 | L4: Tax | M4: =F3/A3 -> 0.12442237 | N4: =F4/A4 -> 0.13549824 | O4: =M4+N4 -> 0.25992062
A5: 5 | B5: Array PCB | C5: 10.8 | D5: =C5/C6 -> 0.041237113 | E5: =E2*$D5 -> 6.9707216 | F5: =F2*$D5 -> 1.1179381 | G5: =G2*$D5 -> 5.9402062 | H5: =H2*$D5 -> 0.11835052 | J5: =(C5+E5+F5+G5+H5)/A5 -> 4.9894433 | L5: Tariff | M5: =G3/A3 -> 0.66112295 | N5: =G4/A4 -> 0.71997499 | O5: =M5+N5 -> 1.3810979
B6: Total parts | C6: =SUM(C3:C5) -> 261.9 | D6: =SUM(D3:D5) -> 1 | E6: =SUM(E3:E5) -> 169.04 | F6: =SUM(F3:F5) -> 27.11 | G6: =SUM(G3:G5) -> 144.05 | H6: =SUM(H3:H5) -> 2.87 | I6: =C6+E6+F6+G6+H6 -> 604.97 | L6: PP Fee | M6: =H3/A3 -> 0.013171974 | N6: =H4/A4 -> 0.014344521 | O6: =M6+N6 -> 0.027516495
L7: TOTAL | M7: =SUM(M2:M6) -> 2.7765328 | N7: =SUM(N2:N6) -> 3.023695 | O7: =M7+N7 -> 5.8002278
A9: Board packs | B9: one set | C9: 6 oz
B10: Two sets | C10: 11 oz

Sheet Ship Sheet
A1: 50 | B1: Fred Krause | C1: WF8Z | D1: 4 | E1: 0 | F1: fakrause@gmail.com | G1: 4538 Mosiman Rd., Middletown, OH 45042-1626 | H1: =5.8*D1 -> 23.2 | I1: 1 | J1: =2*5.51 -> 11.02 | K1: =H1+I1+J1 -> 35.22 | L1: =K1*0.0825 -> 2.90565 | M1: =(K1+L1)*0.05 -> 1.9062825 | N1: =K1+L1+M1 -> 40.031933
B5: Email: | C5: =F1 -> fakrause@gmail.com | E5: Invoiced | G5: =A1 -> 50
B6: Name: | C6: =B1 -> Fred Krause | E6: Funds Recd
B7: Call: | C7: =C1 -> WF8Z | E7: Shipped
B8: Address: | C8: =G1 -> 4538 Mosiman Rd., Middletown, OH 45042-1626
A10: Order: | B10: Quantity | C10: Description | D10: Each | E10: Total Each | F10: Ship wt | L10: Ship Wt Ea
B11: =D1 -> 4 | C11: Teensy Maestro Boardset (PCB+FP) | D11: =Materials!O7 -> 5.8002278 | E11: =D11*B11 -> 23.200911 | F11: =B11*L11 -> 24 | L11: 6
B12: =E1 -> 0 | C12: Teensy Maestro Full Kit | D12: =0 -> 0 | E12: =D12*B12 -> 0 | F12: =B12*L12 -> 0 | L12: 0
C13: Total MDSE | E13: =SUM(E11:E12) -> 23.200911 | F13: =SUM(F11:F12) -> 24
C14: Envelope(s) | E14: =I1 -> 1
C15: Shipping | E15: =J1 -> 11.02 | F15: ^
C16: Semi | E16: =SUM(E13:E15) -> 35.220911
C17: Sales Tax @8.25% | E17: =E16*0.0825 -> 2.9057252
C18: Paypal Fee @5% | E18: =(E16+E17)*0.05 -> 1.9063318
C19: TOTAL | E19: =E16+E17+E18 -> 40.032968
